Workbook

Sheet Zones
A1: Label | B1: Id | C1: Icon | D1: Order
A2: Pricing | B2: =IF(A2="","",LOWER(A2)) -> pricing | C2: LocalOffer | D2: =IF(A2="","",1) -> 1
A3: Web | B3: =IF(A3="","",LOWER(A3)) -> web | C3: Language | D3: =IF(A3="","",D2+1) -> 2
A4: Tour de Contrôle | B4: tourdecontrole | C4: CellTower | D4: =IF(A4="","",D3+1) -> 3
A5: Marketplace | B5: =IF(A5="","",_xlfn.REGEXREPLACE(LOWER(A5)," ","-")) -> marketplace | C5: Storefront | D5: =IF(A5="","",D4+1) -> 4
A6: Magasins | B6: =IF(A6="","",_xlfn.REGEXREPLACE(LOWER(A6)," ","-")) -> magasins | C6: Store | D6: =IF(A6="","",D5+1) -> 5
B8: =IF(A8="","",LOWER(A8)) | C8: =IF(A8="","",_xlfn.CONCAT("svg-",B8)) | D8: =IF(A8="","",D7+1)
B9: =IF(A9="","",LOWER(A9)) | C9: =IF(A9="","",_xlfn.CONCAT("svg-",B9)) | D9: =IF(A9="","",D8+1)

Sheet Templates
A1: Label | B1: Id | C1: Icon | D1: Order | E1: Zone
A2: Magasin unitaire | B2: =IF(A1="","",_xlfn.REGEXREPLACE(_xlfn.REGEXREPLACE(LOWER(A2)," / "," ")," ","-")) -> magasin-unitaire | C2: Store | D2: 1 | E2: magasins
A3: Variation des ventes | B3: =IF(A2="","",_xlfn.REGEXREPLACE(_xlfn.REGEXREPLACE(LOWER(A3)," / "," ")," ","-")) -> variation-des-ventes | C3: TrendingUp | D3: =IF(A3="","",D2+1) -> 2 | E3: web
A4: Recherche produit | B4: =IF(A3="","",_xlfn.REGEXREPLACE(_xlfn.REGEXREPLACE(LOWER(A4)," / "," ")," ","-")) -> recherche-produit | C4: TravelExplore | D4: =IF(A4="","",D3+1) -> 3 | E4: web
A5: Panier | B5: echec-checkout | C5: RemoveShoppingCart | D5: =IF(A5="","",D4+1) -> 4 | E5: web
A6: Suivi applications des OP | B6: =IF(A5="","",_xlfn.REGEXREPLACE(_xlfn.REGEXREPLACE(LOWER(A6)," / "," ")," ","-")) -> suivi-applications-des-op | C6: LocalOffer | D6: =IF(A6="","",D5+1) -> 5 | E6: pricing
A7: Suivi des changements de prix | B7: =IF(A6="","",_xlfn.REGEXREPLACE(_xlfn.REGEXREPLACE(LOWER(A7)," / "," ")," ","-")) -> suivi-des-changements-de-prix | C7: PriceCheck | D7: =IF(A7="","",D6+1) -> 6 | E7: pricing
A8: Volumétrie de prix vers caisses | B8: volumetrie-de-prix-vers-caisses | C8: ShoppingCart | D8: =IF(A8="","",D7+1) -> 7 | E8: pricing

Sheet Domains
A1: Label | B1: Id | C1: Order | D1: Icon
A2: Magasins | B2: magasins | C2: 1 | D2: Store
A3: Siège | B3: general | C3: 2 | D3: Dashboard
A4: Suivi des indicateurs pricing | B4: pricing | C4: 3 | D4: PriceChange

Sheet Categories
A1: Label | B1: Id | C1: Icon | D1: Order | E1: Domain
A2: Suivi des indicateurs web | B2: =IF(#REF!="","",_xlfn.REGEXREPLACE(_xlfn.REGEXREPLACE(LOWER(A2)," / "," ")," ","-")) -> #REF! | C2: Language | D2: =IF(A2="","",#REF!+1) -> #REF! | E2: general
A3: Suivi des indicateurs pricing | B3: Digital-Business-panier-moyen | C3: PriceChange | D3: =IF(A3="","",D2+1) -> #REF! | E3: general
B4: =IF(A4="","",LOWER(A4)) | C4: =IF(A4="","",_xlfn.CONCAT("svg-",B4))
B5: =IF(A5="","",LOWER(A5)) | C5: =IF(A5="","",_xlfn.CONCAT("svg-",B5)) | D5: =IF(A5="","",D4+1)
B6: =IF(A6="","",LOWER(A6)) | C6: =IF(A6="","",_xlfn.CONCAT("svg-",B6)) | D6: =IF(A6="","",D5+1)
B7: =IF(A7="","",LOWER(A7)) | C7: =IF(A7="","",_xlfn.CONCAT("svg-",B7)) | D7: =IF(A7="","",D6+1)
B8: =IF(A8="","",LOWER(A8)) | C8: =IF(A8="","",_xlfn.CONCAT("svg-",B8)) | D8: =IF(A8="","",D7+1)
B9: =IF(A9="","",LOWER(A9)) | C9: =IF(A9="","",_xlfn.CONCAT("svg-",B9)) | D9: =IF(A9="","",D8+1)
B10: =IF(A10="","",LOWER(A10)) | C10: =IF(A10="","",_xlfn.CONCAT("svg-",B10)) | D10: =IF(A10="","",D9+1)
B11: =IF(A11="","",LOWER(A11)) | C11: =IF(A11="","",_xlfn.CONCAT("svg-",B11)) | D11: =IF(A11="","",D10+1)
B12: =IF(A12="","",LOWER(A12)) | C12: =IF(A12="","",_xlfn.CONCAT("svg-",B12)) | D12: =IF(A12="","",D11+1)
B13: =IF(A13="","",LOWER(A13)) | C13: =IF(A13="","",_xlfn.CONCAT("svg-",B13)) | D13: =IF(A13="","",D12+1)
B14: =IF(A14="","",LOWER(A14)) | C14: =IF(A14="","",_xlfn.CONCAT("svg-",B14)) | D14: =IF(A14="","",D13+1)
B15: =IF(A15="","",LOWER(A15)) | C15: =IF(A15="","",_xlfn.CONCAT("svg-",B15)) | D15: =IF(A15="","",D14+1)
B16: =IF(A16="","",LOWER(A16)) | C16: =IF(A16="","",_xlfn.CONCAT("svg-",B16)) | D16: =IF(A16="","",D15+1)
... B40: =IF(A40="","",LOWER(A40)) | C40: =IF(A40="","",_xlfn.CONCAT("svg-",B40)) | D40: =IF(A40="","",D39+1)

Sheet Element Discoveries
A1: Template | B1: Label | C1: Category | D1: Id | E1: Domain | F1: Order | G1: Discovery Template Id | H1: File | I1: Discovery Rule Id | J1: CSV Column
A2: magasin-unitaire | B2: {#SITE_NAME} | C2: Castorama | D2: magasins-{#SITE_ID}-castorama | E2: magasins | F2: {#SITE_ID} | G2: csv-magasins-list | H2: /sftp/upload/list_magasins.csv | I2: magasins-discovery | J2: SITE_ID;SITE_NAME
A3: magasin-unitaire | B3: {#SITE_NAME} | C3: suivi-des-indicateurs-pricing | D3: pricing-{#SITE_ID}-suivi-des-indicateurs-pricing | E3: pricing | F3: {#SITE_ID} | G3: csv-magasins-list | H3: /sftp/upload/list_magasins.csv | I3: magasins-discovery | J3: SITE_ID;SITE_NAME
A4: csv-pricing-magasin-caisses;csv-pricing-magasin-etiquettes-electronique;csv-pricing-magasin-etiquettes-papier;csv-pricing-magasin-vue-web | D4: pricing-magasins-{#SITE_ID}-castorama | F4: {#SITE_ID} | G4: csv-magasins-list | H4: /sftp/upload/list_magasins.csv | I4: magasins-discovery | J4: SITE_ID;SITE_NAME

Sheet Elements
A1: Template | B1: Label | C1: Category | D1: Id | E1: Domain | F1: Order
A2: variation-des-ventes | C2: suivi-des-indicateurs-web | D2: =IF(A2="","",_xlfn.CONCAT(E2,"-",A2,"-",_xlfn.XLOOKUP(C2,Categories!$B$2:$B$989,Categories!$B$2:$B$989))) -> #N/A | E2: general | F2: 2
A3: recherche-produit | C3: suivi-des-indicateurs-web | D3: =IF(A3="","",_xlfn.CONCAT(E3,"-",A3,"-",_xlfn.XLOOKUP(C3,Categories!$B$2:$B$989,Categories!$B$2:$B$989))) -> #N/A | E3: general | F3: 3
A4: echec-checkout | C4: suivi-des-indicateurs-web | D4: =IF(A4="","",_xlfn.CONCAT(E4,"-",A4,"-",_xlfn.XLOOKUP(C4,Categories!$B$2:$B$989,Categories!$B$2:$B$989))) -> #N/A | E4: general | F4: 4
A5: suivi-applications-des-op | C5: suivi-des-indicateurs-pricing | D5: =IF(A5="","",_xlfn.CONCAT(E5,"-",A5,"-",_xlfn.XLOOKUP(C5,Categories!$B$2:$B$989,Categories!$B$2:$B$989))) -> #N/A | E5: general | F5: 5
A6: suivi-des-changements-de-prix | C6: suivi-des-indicateurs-pricing | D6: =IF(A6="","",_xlfn.CONCAT(E6,"-",A6,"-",_xlfn.XLOOKUP(C6,Categories!$B$2:$B$989,Categories!$B$2:$B$989))) -> #N/A | E6: general | F6: 6
A7: volumetrie-de-prix-vers-caisses | C7: suivi-des-indicateurs-pricing | D7: =IF(A7="","",_xlfn.CONCAT(E7,"-",A7,"-",_xlfn.XLOOKUP(C7,Categories!$B$2:$B$989,Categories!$B$2:$B$989))) -> #N/A | E7: general | F7: 7

Sheet Items
A1: Id | B1: Key | C1: Label | D1: Order | E1: Template | F1: Type | G1: Formula | H1: Preprocessing | I1: Donnée | J1: Fichier | K1: Avancement POC
A2: magasins-unitaire-pricing-caisse | B2: =_xlfn.REGEXREPLACE(A2,"-",".") -> magasins.unitaire.pricing.caisse | C2: Caisse | D2: 1 | E2: magasin-unitaire | F2: calculated | G2: avg(last_foreach(/*/caisses.article.wrong.count?[(tag="site_id:{$SITE_ID}")])) | I2: compte unique de article number pour chaque magasin (ou vide ou CF01) | J2: CAFR_SEAMLESS_PRICE_RECON | K2: TRUE
A3: magasins-unitaire-pricing-etiquettes-electroniques | B3: =_xlfn.REGEXREPLACE(A3,"-",".") -> magasins.unitaire.pricing.etiquettes.electroniques | C3: Etiquettes Electroniques | D3: 2 | E3: magasin-unitaire | F3: calculated | G3: avg(last_foreach(/*/etiquettes-electronique.article.wrong.count?[(tag="site_id:{$SITE_ID}")])) | I3: compte unique de article number pour chaque magasin (ou vide ou CF01) | J3: CAFR_PRICER_PRICE_RECON | K3: TRUE
A4: magasins-unitaire-pricing-etiquettes-papier | B4: =_xlfn.REGEXREPLACE(A4,"-",".") -> magasins.unitaire.pricing.etiquettes.papier | C4: Etiquettes Papier | D4: 3 | E4: magasin-unitaire | F4: calculated | G4: avg(last_foreach(/*/etiquettes-papier.article.wrong.count?[(tag="site_id:{$SITE_ID}")])) | I4: compte unique de article number pour chaque magasin (ou vide ou CF01) | J4: CAFR_RES_PRICE_RECON | K4: TRUE
A5: magasins-unitaire-pricing-vue-web-magasin | B5: =_xlfn.REGEXREPLACE(A5,"-",".") -> magasins.unitaire.pricing.vue.web.magasin | C5: Vue Web Magasin | D5: 4 | E5: magasin-unitaire | F5: calculated | G5: avg(last_foreach(/*/vue-web-magasin.article.wrong.count?[(tag="site_id:{$SITE_ID}")])) | I5: compte unique de article number pour chaque magasin (ou vide ou CF01) | J5: CF01_ATG_PRICE_RECON | K5: TRUE
A6: magasins-unitaire-pricing-appli-commande-magasin | B6: =_xlfn.REGEXREPLACE(A6,"-",".") -> magasins.unitaire.pricing.appli.commande.magasin | C6: Appli commande magasin | D6: 5 | E6: magasin-unitaire | F6: disabled | G6: return Math.floor(Math.random() * 10); | I6: compte unique de article number pour chaque magasin (ou vide ou CF01) | J6: Pas encore de fichier | K6: FALSE
A7: variation-des-ventes-global | B7: =_xlfn.REGEXREPLACE(A7,"-",".") -> variation.des.ventes.global | C7: Global | D7: 6 | E7: variation-des-ventes | F7: script | G7: return Math.round(100 * (Math.random() - 0.5)); | I7: Pas pour le moment car fichier inutilisable | K7: FALSE
A8: kpi-suivi-application-des-op-mise-a-jour-SAP | B8: =_xlfn.REGEXREPLACE(A8,"-",".") -> kpi.suivi.application.des.op.mise.a.jour.SAP | C8: Mise à jour SAP | D8: 7 | E8: suivi-applications-des-op | F8: script | G8: return Math.floor(Math.random() * 60); | I8: Pas pour le POC | K8: FALSE
A9: kpi-suivi-application-des-op-caisse | B9: =_xlfn.REGEXREPLACE(A9,"-",".") -> kpi.suivi.application.des.op.caisse | C9: Caisse | D9: 8 | E9: suivi-applications-des-op | F9: calculated | G9: concat("{\"magasin\":",last(/pricing-general-suivi-des-indicateurs-pricing/caisses.magasin.wrong.count.op),",\"produit\":",last(/pricing-general-suivi-des-indicateurs-pricing/caisses.article-by-store.wrong.count.op),"}") | H9: var jsonValue = JSON.parse(value); if (jsonValue.produit > 9) { return "fatal"; } else if (jsonValue.magasin > 9) { return "critical"; } else if (jsonValue.magasin > 0) { return "warning"; } else { return "ok"; } | I9: Regarder pour faire le calcul dans l'item et non le trigger | K9: TRUE
A10: kpi-suivi-application-des-op-etiquettes-electroniques | B10: =_xlfn.REGEXREPLACE(A10,"-",".") -> kpi.suivi.application.des.op.etiquettes.electroniques | C10: Etiquettes Electroniques | D10: 11 | E10: suivi-applications-des-op | F10: calculated | G10: concat("{\"magasin\":",last(/pricing-general-suivi-des-indicateurs-pricing/etiquettes-electronique.magasin.wrong.count.op),",\"produit\":",last(/pricing-general-suivi-des-indicateurs-pricing/etiquettes-electronique.article-by-store.wrong.count.op),"}") | H10: var jsonValue = JSON.parse(value); if (jsonValue.produit > 9) { return "fatal"; } else if (jsonValue.magasin > 9) { return "critical"; } else if (jsonValue.magasin > 0) { return "warning"; } else { return "ok"; } | I10: Regarder pour faire le calcul dans l'item et non le trigger | K10: TRUE
A11: kpi-suivi-application-des-op-etiquettes-papier | B11: =_xlfn.REGEXREPLACE(A11,"-",".") -> kpi.suivi.application.des.op.etiquettes.papier | C11: Etiquettes Papier | D11: 14 | E11: suivi-applications-des-op | F11: calculated | G11: concat("{\"magasin\":",last(/pricing-general-suivi-des-indicateurs-pricing/etiquettes-papier.magasin.wrong.count.op),",\"produit\":",last(/pricing-general-suivi-des-indicateurs-pricing/etiquettes-papier.article-by-store.wrong.count.op),"}") | H11: var jsonValue = JSON.parse(value); if (jsonValue.produit > 9) { return "fatal"; } else if (jsonValue.magasin > 9) { return "critical"; } else if (jsonValue.magasin > 0) { return "warning"; } else { return "ok"; } | I11: Regarder pour faire le calcul dans l'item et non le trigger | K11: TRUE
A12: kpi-suivi-application-des-op-vue-web-magasin | B12: =_xlfn.REGEXREPLACE(A12,"-",".") -> kpi.suivi.application.des.op.vue.web.magasin | C12: Vue Web Magasin | D12: 17 | E12: suivi-applications-des-op | F12: calculated | G12: concat("{\"magasin\":",last(/pricing-general-suivi-des-indicateurs-pricing/vue-web.magasin.wrong.count.op),",\"produit\":",last(/pricing-general-suivi-des-indicateurs-pricing/vue-web.article-by-store.wrong.count.op),"}") | H12: var jsonValue = JSON.parse(value); if (jsonValue.produit > 9) { return "fatal"; } else if (jsonValue.magasin > 9) { return "critical"; } else if (jsonValue.magasin > 0) { return "warning"; } else { return "ok"; } | I12: Regarder pour faire le calcul dans l'item et non le trigger | K12: TRUE
A13: kpi-suivi-application-des-op-appli-commande-magasin | B13: =_xlfn.REGEXREPLACE(A13,"-",".") -> kpi.suivi.application.des.op.appli.commande.magasin | C13: Appli commande magasin | D13: 20 | E13: suivi-applications-des-op | F13: script | G13: return 0; | I13: Pas pour le POC | J13: Pas encore de fichier | K13: FALSE
A14: kpi-suivi-des-changements-de-prix-mise-a-jour-SAP | B14: =_xlfn.REGEXREPLACE(A14,"-",".") -> kpi.suivi.des.changements.de.prix.mise.a.jour.SAP | C14: Mise à jour SAP | D14: 23 | E14: suivi-des-changements-de-prix | F14: script | G14: return Math.floor(Math.random() * 60); | I14: Pas pour le POC | K14: FALSE
A15: kpi-suivi-des-changements-de-prix-caisse | B15: =_xlfn.REGEXREPLACE(A15,"-",".") -> kpi.suivi.des.changements.de.prix.caisse | C15: Caisse | D15: 24 | E15: suivi-des-changements-de-prix | F15: calculated | G15: concat("{\"magasin\":",last(/pricing-general-suivi-des-indicateurs-pricing/caisses.magasin.wrong.count.not-op),",\"produit\":",last(/pricing-general-suivi-des-indicateurs-pricing/caisses.article-by-store.wrong.count.not-op),"}") | H15: var jsonValue = JSON.parse(value); if (jsonValue.produit > 9) { return "fatal"; } else if (jsonValue.magasin > 9) { return "critical"; } else if (jsonValue.magasin > 0) { return "warning"; } else { return "ok"; } | I15: Regarder pour faire le calcul dans l'item et non le trigger | K15: TRUE
A16: kpi-suivi-des-changements-de-prix-etiquettes-electroniques | B16: =_xlfn.REGEXREPLACE(A16,"-",".") -> kpi.suivi.des.changements.de.prix.etiquettes.electroniques | C16: Etiquettes Electroniques | D16: 27 | E16: suivi-des-changements-de-prix | F16: calculated | G16: concat("{\"magasin\":",last(/pricing-general-suivi-des-indicateurs-pricing/etiquettes-electronique.magasin.wrong.count.not-op),",\"produit\":",last(/pricing-general-suivi-des-indicateurs-pricing/etiquettes-electronique.article-by-store.wrong.count.not-op),"}") | H16: var jsonValue = JSON.parse(value); if (jsonValue.produit > 9) { return "fatal"; } else if (jsonValue.magasin > 9) { return "critical"; } else if (jsonValue.magasin > 0) { return "warning"; } else { return "ok"; } | I16: Regarder pour faire le calcul dans l'item et non le trigger | K16: TRUE
A17: kpi-suivi-des-changements-de-prix-etiquettes-papier | B17: =_xlfn.REGEXREPLACE(A17,"-",".") -> kpi.suivi.des.changements.de.prix.etiquettes.papier | C17: Etiquettes Papier | D17: 30 | E17: suivi-des-changements-de-prix | F17: calculated | G17: concat("{\"magasin\":",last(/pricing-general-suivi-des-indicateurs-pricing/etiquettes-papier.magasin.wrong.count.not-op),",\"produit\":",last(/pricing-general-suivi-des-indicateurs-pricing/etiquettes-papier.article-by-store.wrong.count.not-op),"}") | H17: var jsonValue = JSON.parse(value); if (jsonValue.produit > 9) { return "fatal"; } else if (jsonValue.magasin > 9) { return "critical"; } else if (jsonValue.magasin > 0) { return "warning"; } else { return "ok"; } | I17: Regarder pour faire le calcul dans l'item et non le trigger | K17: TRUE
A18: kpi-suivi-des-changements-de-prix-vue-web-magasin | B18: =_xlfn.REGEXREPLACE(A18,"-",".") -> kpi.suivi.des.changements.de.prix.vue.web.magasin | C18: Vue Web Magasin | D18: 33 | E18: suivi-des-changements-de-prix | F18: calculated | G18: concat("{\"magasin\":",last(/pricing-general-suivi-des-indicateurs-pricing/vue-web.magasin.wrong.count.not-op),",\"produit\":",last(/pricing-general-suivi-des-indicateurs-pricing/vue-web.article-by-store.wrong.count.not-op),"}") | H18: var jsonValue = JSON.parse(value); if (jsonValue.produit > 9) { return "fatal"; } else if (jsonValue.magasin > 9) { return "critical"; } else if (jsonValue.magasin > 0) { return "warning"; } else { return "ok"; } | I18: Regarder pour faire le calcul dans l'item et non le trigger | K18: TRUE
A19: kpi-suivi-des-changements-de-prix-appli-commande-magasin | B19: =_xlfn.REGEXREPLACE(A19,"-",".") -> kpi.suivi.des.changements.de.prix.appli.commande.magasin | C19: Appli commande magasin | D19: 36 | E19: suivi-des-changements-de-prix | F19: script | G19: return "ok"; | I19: Pas pour le POC | J19: Pas encore de fichier | K19: FALSE
A20: recherche-produit-global | B20: =_xlfn.REGEXREPLACE(A20,"-",".") -> recherche.produit.global | C20: Global | D20: 39 | E20: recherche-produit | F20: script | G20: return Math.floor(Math.random() * 15) ; | J20: Pas encore de fichier | K20: FALSE
A21: echec-checkout-global | B21: =_xlfn.REGEXREPLACE(A21,"-",".") -> echec.checkout.global | C21: Global | D21: 41 | E21: echec-checkout | F21: script | G21: return Math.floor(Math.random() * 15) ; | J21: Pas encore de fichier | K21: FALSE
A22: volumetrie-de-prix-vers-caisses-castorama | B22: =_xlfn.REGEXREPLACE(A22,"-",".") -> volumetrie.de.prix.vers.caisses.castorama | C22: Global | D22: 43 | E22: volumetrie-de-prix-vers-caisses | F22: calculated | G22: last(/general-volumetrie-prix-caisses/volumetrie-prix-caisses) | I22: Feuille DAY_ALL -> I9 -> Récupérer valeur numéraire (format américain) | J22: Casto FR Price Estimate Report | K22: TRUE

Sheet Triggers
A1: Template | B1: texte | C1: statut | D1: valeur | E1: condition | P1: localisation | T1: statut | V1: zones importantes
A2: magasins-unitaire-pricing-caisse | B2: {ITEM.LASTVALUE} prix différent(s) au niveau des caisses | C2: WARNING | D2: magasins.unitaire.pricing.caisse>0;magasins.unitaire.pricing.caisse<10; | E2: si au moins un prix est different | P2: =Categories!A2 -> Suivi des indicateurs web | T2: WARNING | U2: 1 | V2: embarquement
A3: magasins-unitaire-pricing-caisse | B3: {ITEM.LASTVALUE} prix différents au niveau des caisses | C3: CRITICAL | D3: magasins.unitaire.pricing.caisse>9; | E3: si 10 prix sont differents | T3: FATAL | U3: 3 | V3: PAF
A4: magasins-unitaire-pricing-etiquettes-electroniques | B4: {ITEM.LASTVALUE} prix différent(s) au niveau des étiquettes électroniques | C4: WARNING | D4: magasins.unitaire.pricing.etiquettes.electroniques>0 | E4: si au moins un prix est different
A5: magasins-unitaire-pricing-etiquettes-papier | B5: {ITEM.LASTVALUE} prix différent(s) au niveau des étiquettes papier | C5: WARNING | D5: magasins.unitaire.pricing.etiquettes.papier>0 | E5: si au moins un prix est different
A6: magasins-unitaire-pricing-vue-web-magasin | B6: {ITEM.LASTVALUE} prix différent(s) au niveau de la vue web magasin | C6: WARNING | D6: magasins.unitaire.pricing.vue.web.magasin>0;magasins.unitaire.pricing.vue.web.magasin<10; | E6: si au moins un prix est different
A7: magasins-unitaire-pricing-vue-web-magasin | B7: {ITEM.LASTVALUE} prix différents pour 1 magasin au niveau de la vue web magasin | C7: CRITICAL | D7: magasins.unitaire.pricing.vue.web.magasin>9 | E7: si 10 prix sont differents
A8: magasins-unitaire-pricing-appli-commande-magasin | B8: {ITEM.LASTVALUE} prix différent(s) au niveau de l'appli commande magasin | C8: WARNING | D8: magasins.unitaire.pricing.appli.commande.magasin>0 | E8: si au moins un prix est different
A9: variation-des-ventes-global | B9: Volume de commande anormal ({ITEM.LASTVALUE}%) | C9: WARNING | D9: variation.des.ventes.global>14;variation.des.ventes.global<30 | E9: si >15% et <30% d'ecart
A10: variation-des-ventes-global | B10: Volume de commande anormal ({ITEM.LASTVALUE}%) | C10: CRITICAL | D10: variation.des.ventes.global>29;variation.des.ventes.global<50 | E10: si >30% <50%d'ecart
A11: kpi-suivi-application-des-op-mise-a-jour-SAP | B11: {ITEM.LASTVALUE} prix différent(s) dans ce qui a été saisi sous SAP | C11: WARNING | D11: kpi.suivi.application.des.op.mise.a.jour.SAP>0;kpi.suivi.application.des.op.mise.a.jour.SAP<10 | E11: si au moins un prix est different
A12: kpi-suivi-application-des-op-mise-a-jour-SAP | B12: {ITEM.LASTVALUE} prix différents dans ce qui a été saisi sous SAP | C12: CRITICAL | D12: kpi.suivi.application.des.op.mise.a.jour.SAP>9 | E12: si 10 prix sont differents
A13: kpi-suivi-application-des-op-caisse | B13: Au moins un prix est différent au niveau des caisses | C13: WARNING | D13: kpi.suivi.application.des.op.caisse="warning" | E13: si au moins un prix est different pour un magasin
A14: kpi-suivi-application-des-op-caisse | B14: 10 prix sont différents au niveau des caisses | C14: CRITICAL | D14: kpi.suivi.application.des.op.caisse="fatal" | E14: si 10 prix sont differents pour un magasin
A15: kpi-suivi-application-des-op-etiquettes-electroniques | B15: Au moins un prix est différent au niveau des étiquettes électroniques | C15: WARNING | D15: kpi.suivi.application.des.op.etiquettes.electroniques="warning" | E15: si au moins un prix est different pour un magasin
... A40: volumetrie-de-prix-vers-caisses-castorama | B40: Risque depasse sur le chargement des prix ({ITEM.LASTVALUE}) | C40: CRITICAL | D40: volumetrie.de.prix.vers.caisses.castorama>29999 | E40: si la taille de donnees envoyee est supérieure à 30K

Sheet alert list
A1: type | B1: Id (item) | C1: nom de l'indicateur (label) | D1: lieu d'incidence | E1: localisation (host) | F1: valeur de l'indicateur | G1: statut | H1: valeur | I1: message d'alerte
A2: =VLOOKUP(B2,Items!$A$1:$E$56,4,FALSE) -> #N/A | B2: SEC-DISPO-SIDES | C2: =VLOOKUP(B2,Items!$A$1:$C$56,2,FALSE) -> #N/A | E2: =VLOOKUP(B2,Items!$A$2:$D$56,3,FALSE) -> #N/A | F2: moins de 2 camions disponibles | G2: =VLOOKUP(F2,Triggers!$B$2:$C$144,2,FALSE) -> #N/A | H2: =VLOOKUP(F2,Triggers!$B$2:$E$144,3,FALSE) -> #N/A | I2: =VLOOKUP(F2,Triggers!$B$2:$E$144,4,FALSE) -> #N/A
A3: =VLOOKUP(B3,Items!$A$1:$E$56,4,FALSE) -> #N/A | B3: SEC-DISPO-ZODIAC | C3: =VLOOKUP(B3,Items!$A$1:$C$56,2,FALSE) -> #N/A | E3: =VLOOKUP(B3,Items!$A$2:$D$56,3,FALSE) -> #N/A | F3: un jetski HS | G3: =VLOOKUP(F3,Triggers!$B$2:$C$144,2,FALSE) -> #N/A | H3: =VLOOKUP(F3,Triggers!$B$2:$E$144,3,FALSE) -> #N/A | I3: =VLOOKUP(F3,Triggers!$B$2:$E$144,4,FALSE) -> #N/A
A4: =VLOOKUP(B4,Items!$A$1:$E$56,4,FALSE) -> #N/A | B4: SEC-STATUS-ISSUES | C4: =VLOOKUP(B4,Items!$A$1:$C$56,2,FALSE) -> #N/A | E4: =VLOOKUP(B4,Items!$A$2:$D$56,3,FALSE) -> #N/A | F4: une porte IS HS par zone de sécurité | G4: =VLOOKUP(F4,Triggers!$B$2:$C$144,2,FALSE) -> #N/A | H4: =VLOOKUP(F4,Triggers!$B$2:$E$144,3,FALSE) -> #N/A | I4: =VLOOKUP(F4,Triggers!$B$2:$E$144,4,FALSE) -> #N/A
A5: =VLOOKUP(B5,Items!$A$1:$E$56,4,FALSE) -> #N/A | B5: SEC-STATUS-TOURCONTROLE | C5: =VLOOKUP(B5,Items!$A$1:$C$56,2,FALSE) -> #N/A | E5: =VLOOKUP(B5,Items!$A$2:$D$56,3,FALSE) -> #N/A | F5: ligne téléphonique SSLIA indisponible | G5: =VLOOKUP(F5,Triggers!$B$2:$C$144,2,FALSE) -> #N/A | H5: =VLOOKUP(F5,Triggers!$B$2:$E$144,3,FALSE) -> #N/A | I5: =VLOOKUP(F5,Triggers!$B$2:$E$144,4,FALSE) -> #N/A
A6: =VLOOKUP(B6,Items!$A$1:$E$56,4,FALSE) -> #N/A | B6: SEC-STATUS-COMINTERNE | C6: =VLOOKUP(B6,Items!$A$1:$C$56,2,FALSE) -> #N/A | E6: =VLOOKUP(B6,Items!$A$2:$D$56,3,FALSE) -> #N/A | F6: ligne téléphonique indisponible | G6: =VLOOKUP(F6,Triggers!$B$2:$C$144,2,FALSE) -> #N/A | H6: =VLOOKUP(F6,Triggers!$B$2:$E$144,3,FALSE) -> #N/A | I6: =VLOOKUP(F6,Triggers!$B$2:$E$144,4,FALSE) -> #N/A
A7: =VLOOKUP(B7,Items!$A$1:$E$56,4,FALSE) -> #N/A | B7: SEC-DISPO-STOCK | C7: =VLOOKUP(B7,Items!$A$1:$C$56,2,FALSE) -> #N/A | E7: =VLOOKUP(B7,Items!$A$2:$D$56,3,FALSE) -> #N/A | F7: inférieur à 80% | G7: =VLOOKUP(F7,Triggers!$B$2:$C$144,2,FALSE) -> #N/A | H7: =VLOOKUP(F7,Triggers!$B$2:$E$144,3,FALSE) -> #N/A | I7: =VLOOKUP(F7,Triggers!$B$2:$E$144,4,FALSE) -> #N/A
A8: =VLOOKUP(B8,Items!$A$1:$E$56,4,FALSE) -> #N/A | B8: SEC-DISPO-VEHICULE | C8: =VLOOKUP(B8,Items!$A$1:$C$56,2,FALSE) -> #N/A | E8: =VLOOKUP(B8,Items!$A$2:$D$56,3,FALSE) -> #N/A | F8: un véhicule immobilisé | G8: =VLOOKUP(F8,Triggers!$B$2:$C$144,2,FALSE) -> #N/A | H8: =VLOOKUP(F8,Triggers!$B$2:$E$144,3,FALSE) -> #N/A | I8: =VLOOKUP(F8,Triggers!$B$2:$E$144,4,FALSE) -> #N/A
A9: =VLOOKUP(B9,Items!$A$1:$E$56,4,FALSE) -> #N/A | B9: SEC-DISPO-RESERVEDEAU | C9: =VLOOKUP(B9,Items!$A$1:$C$56,2,FALSE) -> #N/A | E9: =VLOOKUP(B9,Items!$A$2:$D$56,3,FALSE) -> #N/A | F9: niveau <80% | G9: =VLOOKUP(F9,Triggers!$B$2:$C$144,2,FALSE) -> #N/A | H9: =VLOOKUP(F9,Triggers!$B$2:$E$144,3,FALSE) -> #N/A | I9: =VLOOKUP(F9,Triggers!$B$2:$E$144,4,FALSE) -> #N/A
A10: =VLOOKUP(B10,Items!$A$1:$E$56,4,FALSE) -> #N/A | B10: SEC-DISPO-BOUCHEINCENDIE | C10: =VLOOKUP(B10,Items!$A$1:$C$56,2,FALSE) -> #N/A | E10: =VLOOKUP(B10,Items!$A$2:$D$56,3,FALSE) -> #N/A | F10: une bouche à incendie HS | G10: =VLOOKUP(F10,Triggers!$B$2:$C$144,2,FALSE) -> #N/A | H10: =VLOOKUP(F10,Triggers!$B$2:$E$144,3,FALSE) -> #N/A | I10: =VLOOKUP(F10,Triggers!$B$2:$E$144,4,FALSE) -> #N/A
A11: =VLOOKUP(B11,Items!$A$1:$E$56,4,FALSE) -> #N/A | B11: BAGA-STATUS-CONTRLBAGSOUTE | C11: =VLOOKUP(B11,Items!$A$1:$C$56,2,FALSE) -> #N/A | D11: Arrival | E11: =VLOOKUP(B11,Items!$A$2:$D$56,3,FALSE) -> #N/A | F11: une ligne HS | G11: =VLOOKUP(F11,Triggers!$B$2:$C$144,2,FALSE) -> #N/A | H11: =VLOOKUP(F11,Triggers!$B$2:$E$144,3,FALSE) -> #N/A | I11: =VLOOKUP(F11,Triggers!$B$2:$E$144,4,FALSE) -> #N/A
A12: =VLOOKUP(B12,Items!$A$1:$E$56,4,FALSE) -> #N/A | B12: BAGA-STATUS-CONTRLBAGSOUTE | C12: =VLOOKUP(B12,Items!$A$1:$C$56,2,FALSE) -> #N/A | D12: Departure | E12: technique-bagages-départ | F12: une ligne HS | G12: =VLOOKUP(F12,Triggers!$B$2:$C$144,2,FALSE) -> #N/A | H12: =VLOOKUP(F12,Triggers!$B$2:$E$144,3,FALSE) -> #N/A | I12: =VLOOKUP(F12,Triggers!$B$2:$E$144,4,FALSE) -> #N/A
A13: =VLOOKUP(B13,Items!$A$1:$E$56,4,FALSE) -> #N/A | B13: BAGA-STATUS-CONTRLBAGSOUTE | C13: =VLOOKUP(B13,Items!$A$1:$C$56,2,FALSE) -> #N/A | D13: Correspondence | E13: technique-bagages-correspondance | F13: une ligne HS | G13: =VLOOKUP(F13,Triggers!$B$2:$C$144,2,FALSE) -> #N/A | H13: =VLOOKUP(F13,Triggers!$B$2:$E$144,3,FALSE) -> #N/A | I13: =VLOOKUP(F13,Triggers!$B$2:$E$144,4,FALSE) -> #N/A
A14: =VLOOKUP(B14,Items!$A$1:$E$56,4,FALSE) -> #N/A | B14: BAGA-STATUS-BLOCAGE | C14: =VLOOKUP(B14,Items!$A$1:$C$56,2,FALSE) -> #N/A | D14: Arrival | E14: =VLOOKUP(B14,Items!$A$2:$D$56,3,FALSE) -> #N/A | F14: 1 heure de blocage | G14: =VLOOKUP(F14,Triggers!$B$2:$C$144,2,FALSE) -> #N/A | H14: =VLOOKUP(F14,Triggers!$B$2:$E$144,3,FALSE) -> #N/A | I14: =VLOOKUP(F14,Triggers!$B$2:$E$144,4,FALSE) -> #N/A
A15: =VLOOKUP(B15,Items!$A$1:$E$56,4,FALSE) -> #N/A | B15: BAGA-STATUS-BLOCAGE | C15: =VLOOKUP(B15,Items!$A$1:$C$56,2,FALSE) -> #N/A | D15: Departure | E15: technique-bagages-départ | F15: 20 minutes de blocage | G15: =VLOOKUP(F15,Triggers!$B$2:$C$144,2,FALSE) -> #N/A | H15: =VLOOKUP(F15,Triggers!$B$2:$E$144,3,FALSE) -> #N/A | I15: =VLOOKUP(F15,Triggers!$B$2:$E$144,4,FALSE) -> #N/A
A16: =VLOOKUP(B16,Items!$A$1:$E$56,4,FALSE) -> #N/A | B16: BAGA-STATUS-BLOCAGE | C16: =VLOOKUP(B16,Items!$A$1:$C$56,2,FALSE) -> #N/A | D16: Correspondence | E16: technique-bagages-correspondance | F16: pas de blocage | G16: =VLOOKUP(F16,Triggers!$B$2:$C$144,2,FALSE) -> #N/A | H16: =VLOOKUP(F16,Triggers!$B$2:$E$144,3,FALSE) -> #N/A | I16: =VLOOKUP(F16,Triggers!$B$2:$E$144,4,FALSE) -> #N/A
A17: =VLOOKUP(B17,Items!$A$1:$E$56,4,FALSE) -> #N/A | B17: BAGA-STATUS-TOMO | C17: =VLOOKUP(B17,Items!$A$1:$C$56,2,FALSE) -> #N/A | D17: Arrival | E17: technique-bagages-arrivée | F17: EDS 1 ou 3 en défaut | G17: =VLOOKUP(F17,Triggers!$B$2:$C$144,2,FALSE) -> #N/A | H17: =VLOOKUP(F17,Triggers!$B$2:$E$144,3,FALSE) -> #N/A | I17: =VLOOKUP(F17,Triggers!$B$2:$E$144,4,FALSE) -> #N/A
A18: =VLOOKUP(B18,Items!$A$1:$E$56,4,FALSE) -> #N/A | B18: BAGA-STATUS-TOMO | C18: =VLOOKUP(B18,Items!$A$1:$C$56,2,FALSE) -> #N/A | D18: Departure | E18: =VLOOKUP(B18,Items!$A$2:$D$56,3,FALSE) -> #N/A | F18: EDS 1 ou 3 en défaut | G18: =VLOOKUP(F18,Triggers!$B$2:$C$144,2,FALSE) -> #N/A | H18: =VLOOKUP(F18,Triggers!$B$2:$E$144,3,FALSE) -> #N/A | I18: =VLOOKUP(F18,Triggers!$B$2:$E$144,4,FALSE) -> #N/A
A19: =VLOOKUP(B19,Items!$A$1:$E$56,4,FALSE) -> #N/A | B19: BAGA-STATUS-TOMO | C19: =VLOOKUP(B19,Items!$A$1:$C$56,2,FALSE) -> #N/A | D19: Correspondence | E19: technique-bagages-correspondance | F19: EDS 1 ou 3 en défaut | G19: =VLOOKUP(F19,Triggers!$B$2:$C$144,2,FALSE) -> #N/A | H19: =VLOOKUP(F19,Triggers!$B$2:$E$144,3,FALSE) -> #N/A | I19: =VLOOKUP(F19,Triggers!$B$2:$E$144,4,FALSE) -> #N/A
A20: =VLOOKUP(B20,Items!$A$1:$E$56,4,FALSE) -> #N/A | B20: BAGA-STATUS-BARCODE | C20: =VLOOKUP(B20,Items!$A$1:$C$56,2,FALSE) -> #N/A | D20: Arrival | E20: technique-bagages-arrivée | F20: Au moins un lecteur HS | G20: =VLOOKUP(F20,Triggers!$B$2:$C$144,2,FALSE) -> #N/A | H20: =VLOOKUP(F20,Triggers!$B$2:$E$144,3,FALSE) -> #N/A | I20: =VLOOKUP(F20,Triggers!$B$2:$E$144,4,FALSE) -> #N/A
A21: =VLOOKUP(B21,Items!$A$1:$E$56,4,FALSE) -> #N/A | B21: BAGA-STATUS-BARCODE | C21: =VLOOKUP(B21,Items!$A$1:$C$56,2,FALSE) -> #N/A | D21: Departure | E21: technique-bagages-départ | F21: Au moins un lecteur HS | G21: =VLOOKUP(F21,Triggers!$B$2:$C$144,2,FALSE) -> #N/A | H21: =VLOOKUP(F21,Triggers!$B$2:$E$144,3,FALSE) -> #N/A | I21: =VLOOKUP(F21,Triggers!$B$2:$E$144,4,FALSE) -> #N/A
A22: =VLOOKUP(B22,Items!$A$1:$E$56,4,FALSE) -> #N/A | B22: BAGA-STATUS-BARCODE | C22: =VLOOKUP(B22,Items!$A$1:$C$56,2,FALSE) -> #N/A | D22: Correspondence | E22: =VLOOKUP(B22,Items!$A$2:$D$56,3,FALSE) -> #N/A | F22: Au moins un lecteur HS | G22: =VLOOKUP(F22,Triggers!$B$2:$C$144,2,FALSE) -> #N/A | H22: =VLOOKUP(F22,Triggers!$B$2:$E$144,3,FALSE) -> #N/A | I22: =VLOOKUP(F22,Triggers!$B$2:$E$144,4,FALSE) -> #N/A
A23: =VLOOKUP(B23,Items!$A$1:$E$56,4,FALSE) -> #N/A | B23: ENRE-DISPO-BLS | C23: =VLOOKUP(B23,Items!$A$1:$C$56,2,FALSE) -> #N/A | E23: =VLOOKUP(B23,Items!$A$2:$D$56,3,FALSE) -> #N/A | F23: 75% des bornes sont disponibles sur la totalité | G23: =VLOOKUP(F23,Triggers!$B$2:$C$144,2,FALSE) -> #N/A | H23: =VLOOKUP(F23,Triggers!$B$2:$E$144,3,FALSE) -> #N/A | I23: =VLOOKUP(F23,Triggers!$B$2:$E$144,4,FALSE) -> #N/A
A24: =VLOOKUP(B24,Items!$A$1:$E$56,4,FALSE) -> #N/A | B24: CLIM-TEMP-ZONECRITIQUE | C24: =VLOOKUP(B24,Items!$A$1:$C$56,2,FALSE) -> #N/A | D24: Arrival | E24: technique-clim-eau-cvc-arrivée | F24: température de 28°C | G24: =VLOOKUP(F24,Triggers!$B$2:$C$144,2,FALSE) -> #N/A | H24: =VLOOKUP(F24,Triggers!$B$2:$E$144,3,FALSE) -> #N/A | I24: =VLOOKUP(F24,Triggers!$B$2:$E$144,4,FALSE) -> #N/A
A25: =VLOOKUP(B25,Items!$A$1:$E$56,4,FALSE) -> #N/A | B25: CLIM-TEMP-ZONECRITIQUE | C25: =VLOOKUP(B25,Items!$A$1:$C$56,2,FALSE) -> #N/A | D25: Departure | E25: =VLOOKUP(B25,Items!$A$2:$D$56,3,FALSE) -> #N/A | F25: température de 28°C | G25: =VLOOKUP(F25,Triggers!$B$2:$C$144,2,FALSE) -> #N/A | H25: =VLOOKUP(F25,Triggers!$B$2:$E$144,3,FALSE) -> #N/A | I25: =VLOOKUP(F25,Triggers!$B$2:$E$144,4,FALSE) -> #N/A
A26: =VLOOKUP(B26,Items!$A$1:$E$56,4,FALSE) -> #N/A | B26: CLIM-TEMP-ZONECRITIQUE | C26: =VLOOKUP(B26,Items!$A$1:$C$56,2,FALSE) -> #N/A | D26: Correspondence | E26: technique-clim-eau-cvc-correspondance | F26: température de 28°C | G26: =VLOOKUP(F26,Triggers!$B$2:$C$144,2,FALSE) -> #N/A | H26: =VLOOKUP(F26,Triggers!$B$2:$E$144,3,FALSE) -> #N/A | I26: =VLOOKUP(F26,Triggers!$B$2:$E$144,4,FALSE) -> #N/A
A27: =VLOOKUP(B27,Items!$A$1:$E$56,4,FALSE) -> #N/A | B27: CLIM-HUMID-ZONECRITIQUE | C27: =VLOOKUP(B27,Items!$A$1:$C$56,2,FALSE) -> #N/A | D27: Arrival | E27: =VLOOKUP(B27,Items!$A$2:$D$56,3,FALSE) -> #N/A | F27: Niveau supérieur à 70 % | G27: =VLOOKUP(F27,Triggers!$B$2:$C$144,2,FALSE) -> #N/A | H27: =VLOOKUP(F27,Triggers!$B$2:$E$144,3,FALSE) -> #N/A | I27: =VLOOKUP(F27,Triggers!$B$2:$E$144,4,FALSE) -> #N/A
A28: =VLOOKUP(B28,Items!$A$1:$E$56,4,FALSE) -> #N/A | B28: CLIM-HUMID-ZONECRITIQUE | C28: =VLOOKUP(B28,Items!$A$1:$C$56,2,FALSE) -> #N/A | D28: Departure | E28: technique-clim-eau-cvc-départ | F28: Niveau supérieur à 70 % | G28: =VLOOKUP(F28,Triggers!$B$2:$C$144,2,FALSE) -> #N/A | H28: =VLOOKUP(F28,Triggers!$B$2:$E$144,3,FALSE) -> #N/A | I28: =VLOOKUP(F28,Triggers!$B$2:$E$144,4,FALSE) -> #N/A
A29: =VLOOKUP(B29,Items!$A$1:$E$56,4,FALSE) -> #N/A | B29: CLIM-HUMID-ZONECRITIQUE | C29: =VLOOKUP(B29,Items!$A$1:$C$56,2,FALSE) -> #N/A | D29: Correspondence | E29: technique-clim-eau-cvc-correspondance | F29: Niveau supérieur à 70 % | G29: =VLOOKUP(F29,Triggers!$B$2:$C$144,2,FALSE) -> #N/A | H29: =VLOOKUP(F29,Triggers!$B$2:$E$144,3,FALSE) -> #N/A | I29: =VLOOKUP(F29,Triggers!$B$2:$E$144,4,FALSE) -> #N/A
A30: =VLOOKUP(B30,Items!$A$1:$E$56,4,FALSE) -> #N/A | B30: CLIM-PROD-EAU | C30: =VLOOKUP(B30,Items!$A$1:$C$56,2,FALSE) -> #N/A | E30: =VLOOKUP(B30,Items!$A$2:$D$56,3,FALSE) -> #N/A | F30: 1 Groupe HS | G30: =VLOOKUP(F30,Triggers!$B$2:$C$144,2,FALSE) -> #N/A | H30: =VLOOKUP(F30,Triggers!$B$2:$E$144,3,FALSE) -> #N/A | I30: =VLOOKUP(F30,Triggers!$B$2:$E$144,4,FALSE) -> #N/A
A31: =VLOOKUP(B31,Items!$A$1:$E$56,4,FALSE) -> #N/A | B31: CLIM-DISTRIB-EAU | C31: =VLOOKUP(B31,Items!$A$1:$C$56,2,FALSE) -> #N/A | E31: =VLOOKUP(B31,Items!$A$2:$D$56,3,FALSE) -> #N/A | F31: Au moins une pompe de distribution en défaut par niveau | G31: =VLOOKUP(F31,Triggers!$B$2:$C$144,2,FALSE) -> #N/A | H31: =VLOOKUP(F31,Triggers!$B$2:$E$144,3,FALSE) -> #N/A | I31: =VLOOKUP(F31,Triggers!$B$2:$E$144,4,FALSE) -> #N/A
A32: =VLOOKUP(B32,Items!$A$1:$E$56,4,FALSE) -> #N/A | B32: CLIM-STATUS-CTA | C32: =VLOOKUP(B32,Items!$A$1:$C$56,2,FALSE) -> #N/A | E32: =VLOOKUP(B32,Items!$A$2:$D$56,3,FALSE) -> #N/A | F32: Température ou pression soufflage = NOK | G32: =VLOOKUP(F32,Triggers!$B$2:$C$144,2,FALSE) -> #N/A | H32: =VLOOKUP(F32,Triggers!$B$2:$E$144,3,FALSE) -> #N/A | I32: =VLOOKUP(F32,Triggers!$B$2:$E$144,4,FALSE) -> #N/A
A33: =VLOOKUP(B33,Items!$A$1:$E$56,4,FALSE) -> #N/A | B33: CLIM-STATUS-PLOMBERIE | C33: =VLOOKUP(B33,Items!$A$1:$C$56,2,FALSE) -> #N/A | E33: =VLOOKUP(B33,Items!$A$2:$D$56,3,FALSE) -> #N/A | F33: 1 bar<xx< 2bar | G33: =VLOOKUP(F33,Triggers!$B$2:$C$144,2,FALSE) -> #N/A | H33: =VLOOKUP(F33,Triggers!$B$2:$E$144,3,FALSE) -> #N/A | I33: =VLOOKUP(F33,Triggers!$B$2:$E$144,4,FALSE) -> #N/A
A34: =VLOOKUP(B34,Items!$A$1:$E$56,4,FALSE) -> #N/A | B34: CLIM-STATUS-VENTELLE-NAO | C34: =VLOOKUP(B34,Items!$A$1:$C$56,2,FALSE) -> #N/A | E34: =VLOOKUP(B34,Items!$A$2:$D$56,3,FALSE) -> #N/A | F34: non fonctionnelle en auto | G34: =VLOOKUP(F34,Triggers!$B$2:$C$144,2,FALSE) -> #N/A | H34: =VLOOKUP(F34,Triggers!$B$2:$E$144,3,FALSE) -> #N/A | I34: =VLOOKUP(F34,Triggers!$B$2:$E$144,4,FALSE) -> #N/A
A35: =VLOOKUP(B35,Items!$A$1:$E$56,4,FALSE) -> #N/A | B35: CLIM-STATUS-PUISDEP | C35: =VLOOKUP(B35,Items!$A$1:$C$56,2,FALSE) -> #N/A | E35: =VLOOKUP(B35,Items!$A$2:$D$56,3,FALSE) -> #N/A | F35: Pluie et puits ouvert | G35: =VLOOKUP(F35,Triggers!$B$2:$C$144,2,FALSE) -> #N/A | H35: =VLOOKUP(F35,Triggers!$B$2:$E$144,3,FALSE) -> #N/A | I35: =VLOOKUP(F35,Triggers!$B$2:$E$144,4,FALSE) -> #N/A
A36: =VLOOKUP(B36,Items!$A$1:$E$56,4,FALSE) -> #N/A | B36: CLIM-STATUS-STATIONMETEO | C36: =VLOOKUP(B36,Items!$A$1:$C$56,2,FALSE) -> #N/A | E36: =VLOOKUP(B36,Items!$A$2:$D$56,3,FALSE) -> #N/A | F36: Détection pluie sur 30 minutes | G36: =VLOOKUP(F36,Triggers!$B$2:$C$144,2,FALSE) -> #N/A | H36: =VLOOKUP(F36,Triggers!$B$2:$E$144,3,FALSE) -> #N/A | I36: =VLOOKUP(F36,Triggers!$B$2:$E$144,4,FALSE) -> #N/A
A37: =VLOOKUP(B37,Items!$A$1:$E$56,4,FALSE) -> #N/A | B37: CLIM-STATUS-DATAC-TEMP | C37: =VLOOKUP(B37,Items!$A$1:$C$56,2,FALSE) -> #N/A | E37: =VLOOKUP(B37,Items!$A$2:$D$56,3,FALSE) -> #N/A | F37: Niveau supérieur à 26°C | G37: =VLOOKUP(F37,Triggers!$B$2:$C$144,2,FALSE) -> #N/A | H37: =VLOOKUP(F37,Triggers!$B$2:$E$144,3,FALSE) -> #N/A | I37: =VLOOKUP(F37,Triggers!$B$2:$E$144,4,FALSE) -> #N/A
A38: =VLOOKUP(B38,Items!$A$1:$E$56,4,FALSE) -> #N/A | B38: CLIM-STATUS-DATAC-HYGRO | C38: =VLOOKUP(B38,Items!$A$1:$C$56,2,FALSE) -> #N/A | E38: =VLOOKUP(B38,Items!$A$2:$D$56,3,FALSE) -> #N/A | F38: Niveau supérieur à 70 % | G38: =VLOOKUP(F38,Triggers!$B$2:$C$144,2,FALSE) -> #N/A | H38: =VLOOKUP(F38,Triggers!$B$2:$E$144,3,FALSE) -> #N/A | I38: =VLOOKUP(F38,Triggers!$B$2:$E$144,4,FALSE) -> #N/A
A39: =VLOOKUP(B39,Items!$A$1:$E$56,4,FALSE) -> #N/A | B39: BAGA-STATUS-TAPIS | C39: =VLOOKUP(B39,Items!$A$1:$C$56,2,FALSE) -> #N/A | D39: Arrival | E39: =VLOOKUP(B39,Items!$A$2:$D$56,3,FALSE) -> #N/A | F39: 1 tapis HS | G39: =VLOOKUP(F39,Triggers!$B$2:$C$144,2,FALSE) -> #N/A | H39: =VLOOKUP(F39,Triggers!$B$2:$E$144,3,FALSE) -> #N/A | I39: =VLOOKUP(F39,Triggers!$B$2:$E$144,4,FALSE) -> #N/A
A40: =VLOOKUP(B40,Items!$A$1:$E$56,4,FALSE) -> #N/A | B40: BAGA-STATUS-TAPIS | C40: =VLOOKUP(B40,Items!$A$1:$C$56,2,FALSE) -> #N/A | D40: Departure | E40: exploitation-bagages-départ | F40: 1 tapis HS | G40: =VLOOKUP(F40,Triggers!$B$2:$C$144,2,FALSE) -> #N/A | H40: =VLOOKUP(F40,Triggers!$B$2:$E$144,3,FALSE) -> #N/A | I40: =VLOOKUP(F40,Triggers!$B$2:$E$144,4,FALSE) -> #N/A
...

Sheet Elements-old
A1: Template | B1: Label | C1: Category | D1: Id | E1: Domain | F1: Order
A2: magasin-unitaire | B2: ENGLOS 2 | C2: castorama | D2: magasins-1477-castorama | E2: magasins | F2: 1
A3: variation-des-ventes | C3: suivi-des-indicateurs-web | D3: =IF(A3="","",_xlfn.CONCAT(E3,"-",A3,"-",_xlfn.XLOOKUP(C3,Categories!$B$2:$B$989,Categories!$B$2:$B$989))) -> #N/A | E3: general | F3: 2
A4: recherche-produit | C4: suivi-des-indicateurs-web | D4: =IF(A4="","",_xlfn.CONCAT(E4,"-",A4,"-",_xlfn.XLOOKUP(C4,Categories!$B$2:$B$989,Categories!$B$2:$B$989))) -> #N/A | E4: general | F4: 3
A5: echec-checkout | C5: suivi-des-indicateurs-web | D5: =IF(A5="","",_xlfn.CONCAT(E5,"-",A5,"-",_xlfn.XLOOKUP(C5,Categories!$B$2:$B$989,Categories!$B$2:$B$989))) -> #N/A | E5: general | F5: 4
A6: suivi-applications-des-op | C6: suivi-des-indicateurs-pricing | D6: =IF(A6="","",_xlfn.CONCAT(E6,"-",A6,"-",_xlfn.XLOOKUP(C6,Categories!$B$2:$B$989,Categories!$B$2:$B$989))) -> #N/A | E6: general | F6: 5
A7: suivi-des-changements-de-prix | C7: suivi-des-indicateurs-pricing | D7: =IF(A7="","",_xlfn.CONCAT(E7,"-",A7,"-",_xlfn.XLOOKUP(C7,Categories!$B$2:$B$989,Categories!$B$2:$B$989))) -> #N/A | E7: general | F7: 6
A8: volumetrie-de-prix-vers-caisses | C8: suivi-des-indicateurs-pricing | D8: =IF(A8="","",_xlfn.CONCAT(E8,"-",A8,"-",_xlfn.XLOOKUP(C8,Categories!$B$2:$B$989,Categories!$B$2:$B$989))) -> #N/A | E8: general | F8: 7
A9: magasin-unitaire | B9: ENGLOS 2 | C9: suivi-des-indicateurs-pricing | D9: pricing-1477-suivi-des-indicateurs-pricing | E9: pricing | F9: 8
A10: magasin-unitaire | B10: BARENTIN 2 | C10: castorama | D10: magasins-1488-castorama | E10: magasins | F10: 9
A11: magasin-unitaire | B11: BONDUES | C11: castorama | D11: magasins-1410-castorama | E11: magasins | F11: 10
A12: magasin-unitaire | B12: CAEN FLEURY | C12: castorama | D12: magasins-1509-castorama | E12: magasins | F12: 11
A13: magasin-unitaire | B13: CAEN HEROUVILLE | C13: castorama | D13: magasins-1438-castorama | E13: magasins | F13: 12
A14: magasin-unitaire | B14: CREIL2 ST MAXIMIN | C14: castorama | D14: magasins-1507-castorama | E14: magasins | F14: 13
A15: magasin-unitaire | B15: DUNKERQUE | C15: castorama | D15: magasins-1461-castorama | E15: magasins | F15: 14
A16: magasin-unitaire | B16: HENIN | C16: castorama | D16: magasins-1448-castorama | E16: magasins | F16: 15
A17: magasin-unitaire | B17: LE HAVRE | C17: castorama | D17: magasins-1489-castorama | E17: magasins | F17: 16
A18: magasin-unitaire | B18: REIMS THILLOIS | C18: castorama | D18: magasins-1500-castorama | E18: magasins | F18: 17
A19: magasin-unitaire | B19: BESANCON | C19: castorama | D19: magasins-1467-castorama | E19: magasins | F19: 18
A20: magasin-unitaire | B20: CHALON SAONE | C20: castorama | D20: magasins-1470-castorama | E20: magasins | F20: 19
... A197: magasin-unitaire | B197: SOLFERINO | C197: suivi-des-indicateurs-pricing | D197: pricing-2601-suivi-des-indicateurs-pricing | E197: pricing | F197: 196

Sheet Items-old
A1: Id | B1: Key | C1: Label | D1: Order | E1: Template | F1: Type | G1: Formula | H1: Preprocessing | I1: Donnée | J1: Fichier | K1: Avancement POC
A2: magasins-unitaire-pricing-caisse | B2: =_xlfn.REGEXREPLACE(A2,"-",".") -> magasins.unitaire.pricing.caisse | C2: Caisse | D2: 1 | E2: magasin-unitaire | F2: calculated | G2: avg(last_foreach(/*/caisses.article.wrong.count?[(tag="site_id:{$SITE_ID}")])) | I2: compte unique de article number pour chaque magasin (ou vide ou CF01) | J2: CAFR_SEAMLESS_PRICE_RECON | K2: TRUE
A3: magasins-unitaire-pricing-etiquettes-electroniques | B3: =_xlfn.REGEXREPLACE(A3,"-",".") -> magasins.unitaire.pricing.etiquettes.electroniques | C3: Etiquettes Electroniques | D3: 2 | E3: magasin-unitaire | F3: calculated | G3: avg(last_foreach(/*/etiquettes-electronique.article.wrong.count?[(tag="site_id:{$SITE_ID}")])) | I3: compte unique de article number pour chaque magasin (ou vide ou CF01) | J3: CAFR_PRICER_PRICE_RECON | K3: TRUE
A4: magasins-unitaire-pricing-etiquettes-papier | B4: =_xlfn.REGEXREPLACE(A4,"-",".") -> magasins.unitaire.pricing.etiquettes.papier | C4: Etiquettes Papier | D4: 3 | E4: magasin-unitaire | F4: calculated | G4: avg(last_foreach(/*/etiquettes-papier.article.wrong.count?[(tag="site_id:{$SITE_ID}")])) | I4: compte unique de article number pour chaque magasin (ou vide ou CF01) | J4: CAFR_RES_PRICE_RECON | K4: TRUE
A5: magasins-unitaire-pricing-vue-web-magasin | B5: =_xlfn.REGEXREPLACE(A5,"-",".") -> magasins.unitaire.pricing.vue.web.magasin | C5: Vue Web Magasin | D5: 4 | E5: magasin-unitaire | F5: calculated | G5: avg(last_foreach(/*/vue-web-magasin.article.wrong.count?[(tag="site_id:{$SITE_ID}")])) | I5: compte unique de article number pour chaque magasin (ou vide ou CF01) | J5: CF01_ATG_PRICE_RECON | K5: TRUE
A6: magasins-unitaire-pricing-appli-commande-magasin | B6: =_xlfn.REGEXREPLACE(A6,"-",".") -> magasins.unitaire.pricing.appli.commande.magasin | C6: Appli commande magasin | D6: 5 | E6: magasin-unitaire | F6: disabled | G6: return Math.floor(Math.random() * 10); | I6: compte unique de article number pour chaque magasin (ou vide ou CF01) | J6: Pas encore de fichier | K6: FALSE
A7: variation-des-ventes-global | B7: =_xlfn.REGEXREPLACE(A7,"-",".") -> variation.des.ventes.global | C7: Variation des ventes | D7: 6 | E7: variation-des-ventes | F7: disabled | G7: return Math.round(3000 * (1 + (Math.random() - 0.5))); | I7: Pas pour le moment car fichier inutilisable | K7: FALSE
A8: kpi-suivi-application-des-op-mise-a-jour-SAP | B8: =_xlfn.REGEXREPLACE(A8,"-",".") -> kpi.suivi.application.des.op.mise.a.jour.SAP | C8: Mise à jour SAP | D8: 7 | E8: suivi-applications-des-op | F8: disabled | G8: return Math.floor(Math.random() * 60); | I8: Pas pour le POC | K8: FALSE
A9: kpi-suivi-application-des-op-caisse | B9: =_xlfn.REGEXREPLACE(A9,"-",".") -> kpi.suivi.application.des.op.caisse | C9: Caisse | D9: 8 | E9: suivi-applications-des-op | F9: calculated | G9: concat("{\"magasin\":",last(/pricing-general-suivi-des-indicateurs-pricing/caisses.magasin.wrong.count.op),",\"produit\":",last(/pricing-general-suivi-des-indicateurs-pricing/caisses.article-by-store.wrong.count.op),"}") | H9: var jsonValue = JSON.parse(value); if (jsonValue.produit > 9) { return "fatal"; } else if (jsonValue.magasin > 9) { return "critical"; } else if (jsonValue.magasin > 0) { return "warning"; } else { return "ok"; } | I9: Regarder pour faire le calcul dans l'item et non le trigger | K9: FALSE
A10: kpi-suivi-application-des-op-caisse-produit | B10: =_xlfn.REGEXREPLACE(A10,"-",".") -> kpi.suivi.application.des.op.caisse.produit | C10: =_xlfn.CONCAT(C9,"- nombre de produits en erreur") -> Caisse- nombre de produits en erreur | D10: 9 | E10: suivi-applications-des-op | F10: calculated | G10: last(/pricing-general-suivi-des-indicateurs-pricing/caisses.article-by-store.wrong.count.op) | I10: Max COUNT(articles) par magasin uniquement si PRICE_TYPE = VKA0 | J10: SAP_OMNI_PROMOPRICE_RECON | K10: TRUE
A11: kpi-suivi-application-des-op-caisse-magasin | B11: =_xlfn.REGEXREPLACE(A11,"-",".") -> kpi.suivi.application.des.op.caisse.magasin | C11: =_xlfn.CONCAT(C9,"- nombre de magasins en erreur") -> Caisse- nombre de magasins en erreur | D11: 10 | E11: suivi-applications-des-op | F11: calculated | G11: last(/pricing-general-suivi-des-indicateurs-pricing/caisses.magasin.wrong.count.op) | I11: Compte unique magasin (STORE_CORE) uniquement si PRICE_TYPE = VKA0 | J11: SAP_OMNI_PROMOPRICE_RECON | K11: TRUE
A12: kpi-suivi-application-des-op-etiquettes-electroniques | B12: =_xlfn.REGEXREPLACE(A12,"-",".") -> kpi.suivi.application.des.op.etiquettes.electroniques | C12: Etiquettes Electroniques | D12: 11 | E12: suivi-applications-des-op | F12: script | I12: Regarder pour faire le calcul dans l'item et non le trigger | K12: FALSE
A13: kpi-suivi-application-des-op-etiquettes-electroniques-produit | B13: =_xlfn.REGEXREPLACE(A13,"-",".") -> kpi.suivi.application.des.op.etiquettes.electroniques.produit | C13: =_xlfn.CONCAT(C12,"- nombre de produits en erreur") -> Etiquettes Electroniques- nombre de produits en erreur | D13: 12 | E13: suivi-applications-des-op | F13: calculated | G13: last(/pricing-general-suivi-des-indicateurs-pricing/etiquettes-electronique.article-by-store.wrong.count.op) | I13: Max COUNT(articles) par magasin uniquement si PRICE_TYPE = VKA0 | J13: CAFR_PRICER_PRICE_RECON | K13: TRUE
A14: kpi-suivi-application-des-op-etiquettes-electroniques-magasin | B14: =_xlfn.REGEXREPLACE(A14,"-",".") -> kpi.suivi.application.des.op.etiquettes.electroniques.magasin | C14: =_xlfn.CONCAT(C12,"- nombre de magasins en erreur") -> Etiquettes Electroniques- nombre de magasins en erreur | D14: 13 | E14: suivi-applications-des-op | F14: calculated | G14: last(/pricing-general-suivi-des-indicateurs-pricing/etiquettes-electronique.magasin.wrong.count.op) | I14: Compte unique magasin (STORE_CORE) uniquement si PRICE_TYPE = VKA0 | J14: CAFR_PRICER_PRICE_RECON | K14: TRUE
A15: kpi-suivi-application-des-op-etiquettes-papier | B15: =_xlfn.REGEXREPLACE(A15,"-",".") -> kpi.suivi.application.des.op.etiquettes.papier | C15: Etiquettes Papier | D15: 14 | E15: suivi-applications-des-op | F15: script | I15: Regarder pour faire le calcul dans l'item et non le trigger | K15: FALSE
A16: kpi-suivi-application-des-op-etiquettes-papier-produit | B16: =_xlfn.REGEXREPLACE(A16,"-",".") -> kpi.suivi.application.des.op.etiquettes.papier.produit | C16: =_xlfn.CONCAT(C15,"- nombre de produits en erreur") -> Etiquettes Papier- nombre de produits en erreur | D16: 15 | E16: suivi-applications-des-op | F16: calculated | G16: last(/pricing-general-suivi-des-indicateurs-pricing/etiquettes-papier.article-by-store.wrong.count.op) | I16: Max COUNT(articles) par magasin uniquement si PRICE_TYPE = VKA0 | J16: CAFR_RES_PRICE_RECON | K16: TRUE
A17: kpi-suivi-application-des-op-etiquettes-papier-magasin | B17: =_xlfn.REGEXREPLACE(A17,"-",".") -> kpi.suivi.application.des.op.etiquettes.papier.magasin | C17: =_xlfn.CONCAT(C15,"- nombre de magasins en erreur") -> Etiquettes Papier- nombre de magasins en erreur | D17: 16 | E17: suivi-applications-des-op | F17: calculated | G17: last(/pricing-general-suivi-des-indicateurs-pricing/etiquettes-papier.magasin.wrong.count.op) | I17: Compte unique magasin (STORE_CORE) uniquement si PRICE_TYPE = VKA0 | J17: CAFR_RES_PRICE_RECON | K17: TRUE
A18: kpi-suivi-application-des-op-vue-web-magasin | B18: =_xlfn.REGEXREPLACE(A18,"-",".") -> kpi.suivi.application.des.op.vue.web.magasin | C18: Vue Web Magasin | D18: 17 | E18: suivi-applications-des-op | F18: script | I18: Regarder pour faire le calcul dans l'item et non le trigger | K18: FALSE
A19: kpi-suivi-application-des-op-vue-web-magasin-produit | B19: =_xlfn.REGEXREPLACE(A19,"-",".") -> kpi.suivi.application.des.op.vue.web.magasin.produit | C19: =_xlfn.CONCAT(C18,"- nombre de produits en erreur") -> Vue Web Magasin- nombre de produits en erreur | D19: 18 | E19: suivi-applications-des-op | F19: calculated | G19: last(/pricing-general-suivi-des-indicateurs-pricing/vue-web.article-by-store.wrong.count.op) | I19: Max COUNT(articles) par magasin uniquement si PRICE_TYPE = VKA0 | J19: CF01_ATG_PRICE_RECON | K19: TRUE
A20: kpi-suivi-application-des-op-vue-web-magasin-magasin | B20: =_xlfn.REGEXREPLACE(A20,"-",".") -> kpi.suivi.application.des.op.vue.web.magasin.magasin | C20: =_xlfn.CONCAT(C18,"- nombre de magasins en erreur") -> Vue Web Magasin- nombre de magasins en erreur | D20: 19 | E20: suivi-applications-des-op | F20: calculated | G20: last(/pricing-general-suivi-des-indicateurs-pricing/vue-web.magasin.wrong.count.op) | I20: Compte unique magasin (STORE_CORE) uniquement si PRICE_TYPE = VKA0 | J20: CF01_ATG_PRICE_RECON | K20: TRUE
A21: kpi-suivi-application-des-op-appli-commande-magasin | B21: =_xlfn.REGEXREPLACE(A21,"-",".") -> kpi.suivi.application.des.op.appli.commande.magasin | C21: Appli commande magasin | D21: 20 | E21: suivi-applications-des-op | F21: script | I21: Pas pour le POC | J21: Pas encore de fichier | K21: FALSE
A22: kpi-suivi-application-des-op-appli-commande-magasin-produit | B22: =_xlfn.REGEXREPLACE(A22,"-",".") -> kpi.suivi.application.des.op.appli.commande.magasin.produit | C22: =_xlfn.CONCAT(C21,"- nombre de produits en erreur") -> Appli commande magasin- nombre de produits en erreur | D22: 21 | E22: suivi-applications-des-op | F22: disabled | G22: return Math.floor(Math.random() * 60) ; | I22: Pas pour le POC | J22: Pas encore de fichier | K22: FALSE
A23: kpi-suivi-application-des-op-appli-commande-magasin-magasin | B23: =_xlfn.REGEXREPLACE(A23,"-",".") -> kpi.suivi.application.des.op.appli.commande.magasin.magasin | C23: =_xlfn.CONCAT(C21,"- nombre de magasins en erreur") -> Appli commande magasin- nombre de magasins en erreur | D23: 22 | E23: suivi-applications-des-op | F23: disabled | G23: return Math.floor(Math.random() < 0.7 ? 1 : Math.floor(Math.random() * 14) + 2); | I23: Pas pour le POC | J23: Pas encore de fichier | K23: FALSE
A24: kpi-suivi-des-changements-de-prix-mise-a-jour-SAP | B24: =_xlfn.REGEXREPLACE(A24,"-",".") -> kpi.suivi.des.changements.de.prix.mise.a.jour.SAP | C24: Mise à jour SAP | D24: 23 | E24: suivi-des-changements-de-prix | F24: disabled | G24: return Math.floor(Math.random() * 60); | I24: Pas pour le POC | K24: FALSE
A25: kpi-suivi-des-changements-de-prix-caisse | B25: =_xlfn.REGEXREPLACE(A25,"-",".") -> kpi.suivi.des.changements.de.prix.caisse | C25: Caisse | D25: 24 | E25: suivi-des-changements-de-prix | F25: script | I25: Regarder pour faire le calcul dans l'item et non le trigger | K25: FALSE
A26: kpi-suivi-des-changements-de-prix-caisse-produit | B26: =_xlfn.REGEXREPLACE(A26,"-",".") -> kpi.suivi.des.changements.de.prix.caisse.produit | C26: =_xlfn.CONCAT(C25,"- nombre de produits en erreur") -> Caisse- nombre de produits en erreur | D26: 25 | E26: suivi-des-changements-de-prix | F26: calculated | G26: last(/pricing-general-suivi-des-indicateurs-pricing/caisses.article-by-store.wrong.count.not-op) | I26: Max COUNT(articles) par magasin uniquement si PRICE_TYPE != VKA0 | J26: CAFR_SEAMLESS_PRICE_RECON | K26: TRUE
A27: kpi-suivi-des-changements-de-prix-caisse-magasin | B27: =_xlfn.REGEXREPLACE(A27,"-",".") -> kpi.suivi.des.changements.de.prix.caisse.magasin | C27: =_xlfn.CONCAT(C25,"- nombre de magasins en erreur") -> Caisse- nombre de magasins en erreur | D27: 26 | E27: suivi-des-changements-de-prix | F27: calculated | G27: last(/pricing-general-suivi-des-indicateurs-pricing/caisses.magasin.wrong.count.not-op) | I27: Compte unique magasin (STORE_CORE) uniquement si PRICE_TYPE != VKA0 | J27: CAFR_SEAMLESS_PRICE_RECON | K27: TRUE
A28: kpi-suivi-des-changements-de-prix-etiquettes-electroniques | B28: =_xlfn.REGEXREPLACE(A28,"-",".") -> kpi.suivi.des.changements.de.prix.etiquettes.electroniques | C28: Etiquettes Electroniques | D28: 27 | E28: suivi-des-changements-de-prix | F28: script | I28: Regarder pour faire le calcul dans l'item et non le trigger | K28: FALSE
A29: kpi-suivi-des-changements-de-prix-etiquettes-electroniques-produit | B29: =_xlfn.REGEXREPLACE(A29,"-",".") -> kpi.suivi.des.changements.de.prix.etiquettes.electroniques.produit | C29: =_xlfn.CONCAT(C28,"- nombre de produits en erreur") -> Etiquettes Electroniques- nombre de produits en erreur | D29: 28 | E29: suivi-des-changements-de-prix | F29: calculated | G29: last(/pricing-general-suivi-des-indicateurs-pricing/etiquettes-electronique.article-by-store.wrong.count.not-op) | I29: Max COUNT(articles) par magasin uniquement si PRICE_TYPE != VKA0 | J29: CAFR_PRICER_PRICE_RECON | K29: TRUE
A30: kpi-suivi-des-changements-de-prix-etiquettes-electroniques-magasin | B30: =_xlfn.REGEXREPLACE(A30,"-",".") -> kpi.suivi.des.changements.de.prix.etiquettes.electroniques.magasin | C30: =_xlfn.CONCAT(C28,"- nombre de magasins en erreur") -> Etiquettes Electroniques- nombre de magasins en erreur | D30: 29 | E30: suivi-des-changements-de-prix | F30: calculated | G30: last(/pricing-general-suivi-des-indicateurs-pricing/etiquettes-electronique.magasin.wrong.count.not-op) | I30: Compte unique magasin (STORE_CORE) uniquement si PRICE_TYPE != VKA0 | J30: CAFR_PRICER_PRICE_RECON | K30: TRUE
A31: kpi-suivi-des-changements-de-prix-etiquettes-papier | B31: =_xlfn.REGEXREPLACE(A31,"-",".") -> kpi.suivi.des.changements.de.prix.etiquettes.papier | C31: Etiquettes Papier | D31: 30 | E31: suivi-des-changements-de-prix | F31: script | I31: Regarder pour faire le calcul dans l'item et non le trigger | K31: FALSE
A32: =_xlfn.CONCAT(A31,"-produit") -> kpi-suivi-des-changements-de-prix-etiquettes-papier-produit | B32: =_xlfn.REGEXREPLACE(A32,"-",".") -> kpi.suivi.des.changements.de.prix.etiquettes.papier.produit | C32: =_xlfn.CONCAT(C31,"- nombre de produits en erreur") -> Etiquettes Papier- nombre de produits en erreur | D32: 31 | E32: suivi-des-changements-de-prix | F32: calculated | G32: last(/pricing-general-suivi-des-indicateurs-pricing/etiquettes-papier.article-by-store.wrong.count.not-op) | I32: Max COUNT(articles) par magasin uniquement si PRICE_TYPE != VKA0 | J32: CAFR_RES_PRICE_RECON | K32: TRUE
A33: =_xlfn.CONCAT(A31,"-magasin") -> kpi-suivi-des-changements-de-prix-etiquettes-papier-magasin | B33: =_xlfn.REGEXREPLACE(A33,"-",".") -> kpi.suivi.des.changements.de.prix.etiquettes.papier.magasin | C33: =_xlfn.CONCAT(C31,"- nombre de magasins en erreur") -> Etiquettes Papier- nombre de magasins en erreur | D33: 32 | E33: suivi-des-changements-de-prix | F33: calculated | G33: last(/pricing-general-suivi-des-indicateurs-pricing/etiquettes-papier.magasin.wrong.count.not-op) | I33: Compte unique magasin (STORE_CORE) uniquement si PRICE_TYPE != VKA0 | J33: CAFR_RES_PRICE_RECON | K33: TRUE
A34: kpi-suivi-des-changements-de-prix-vue-web-magasin | B34: =_xlfn.REGEXREPLACE(A34,"-",".") -> kpi.suivi.des.changements.de.prix.vue.web.magasin | C34: Vue Web Magasin | D34: 33 | E34: suivi-des-changements-de-prix | F34: script | I34: Regarder pour faire le calcul dans l'item et non le trigger | K34: FALSE
A35: =_xlfn.CONCAT(A34,"-produit") -> kpi-suivi-des-changements-de-prix-vue-web-magasin-produit | B35: =_xlfn.REGEXREPLACE(A35,"-",".") -> kpi.suivi.des.changements.de.prix.vue.web.magasin.produit | C35: =_xlfn.CONCAT(C34,"- nombre de produits en erreur") -> Vue Web Magasin- nombre de produits en erreur | D35: 34 | E35: suivi-des-changements-de-prix | F35: calculated | G35: last(/pricing-general-suivi-des-indicateurs-pricing/vue-web.article-by-store.wrong.count.not-op) | I35: Max COUNT(articles) par magasin uniquement si PRICE_TYPE != VKA0 | J35: CF01_ATG_PRICE_RECON | K35: TRUE
A36: =_xlfn.CONCAT(A34,"-magasin") -> kpi-suivi-des-changements-de-prix-vue-web-magasin-magasin | B36: =_xlfn.REGEXREPLACE(A36,"-",".") -> kpi.suivi.des.changements.de.prix.vue.web.magasin.magasin | C36: =_xlfn.CONCAT(C34,"- nombre de magasins en erreur") -> Vue Web Magasin- nombre de magasins en erreur | D36: 35 | E36: suivi-des-changements-de-prix | F36: calculated | G36: last(/pricing-general-suivi-des-indicateurs-pricing/vue-web.magasin.wrong.count.not-op) | I36: Compte unique magasin (STORE_CORE) uniquement si PRICE_TYPE != VKA0 | J36: CF01_ATG_PRICE_RECON | K36: TRUE
A37: kpi-suivi-des-changements-de-prix-appli-commande-magasin | B37: =_xlfn.REGEXREPLACE(A37,"-",".") -> kpi.suivi.des.changements.de.prix.appli.commande.magasin | C37: Appli commande magasin | D37: 36 | E37: suivi-des-changements-de-prix | F37: disabled | G37: return false; | I37: Pas pour le POC | J37: Pas encore de fichier | K37: FALSE
A38: =_xlfn.CONCAT(A37,"-produit") -> kpi-suivi-des-changements-de-prix-appli-commande-magasin-produit | B38: =_xlfn.REGEXREPLACE(A38,"-",".") -> kpi.suivi.des.changements.de.prix.appli.commande.magasin.produit | C38: =_xlfn.CONCAT(C37,"- nombre de produits en erreur") -> Appli commande magasin- nombre de produits en erreur | D38: 37 | E38: suivi-des-changements-de-prix | F38: disabled | G38: return Math.floor(Math.random() * 60) ; | I38: Pas pour le POC | J38: Pas encore de fichier | K38: FALSE
A39: =_xlfn.CONCAT(A37,"-magasin") -> kpi-suivi-des-changements-de-prix-appli-commande-magasin-magasin | B39: =_xlfn.REGEXREPLACE(A39,"-",".") -> kpi.suivi.des.changements.de.prix.appli.commande.magasin.magasin | C39: =_xlfn.CONCAT(C37,"- nombre de magasins en erreur") -> Appli commande magasin- nombre de magasins en erreur | D39: 38 | E39: suivi-des-changements-de-prix | F39: disabled | G39: return Math.floor(Math.random() < 0.7 ? 1 : Math.floor(Math.random() * 14) + 2); | I39: Pas pour le POC | J39: Pas encore de fichier | K39: FALSE
A40: recherche-produit-global | B40: =_xlfn.REGEXREPLACE(A40,"-",".") -> recherche.produit.global | C40: Recherche produit | D40: 39 | E40: recherche-produit | F40: disabled | G40: return Math.floor(Math.random() * 15) ; | J40: Pas encore de fichier | K40: FALSE
...
